[2025-09-25T19:21:15.874+0000] {local_task_job_runner.py:120} INFO - ::group::Pre task execution logs
[2025-09-25T19:21:15.929+0000] {taskinstance.py:2073} INFO - Dependencies all met for dep_context=non-requeueable deps ti=<TaskInstance: test_mariadb_dag.insert_rows manual__2025-09-25T19:20:54.239298+00:00 [queued]>
[2025-09-25T19:21:15.948+0000] {taskinstance.py:2073} INFO - Dependencies all met for dep_context=requeueable deps ti=<TaskInstance: test_mariadb_dag.insert_rows manual__2025-09-25T19:20:54.239298+00:00 [queued]>
[2025-09-25T19:21:15.949+0000] {taskinstance.py:2303} INFO - Starting attempt 1 of 1
[2025-09-25T19:21:15.976+0000] {taskinstance.py:2327} INFO - Executing <Task(MySqlOperator): insert_rows> on 2025-09-25 19:20:54.239298+00:00
[2025-09-25T19:21:15.991+0000] {warnings.py:110} WARNING - /home/***/.local/lib/python3.12/site-packages/***/task/task_runner/standard_task_runner.py:61: DeprecationWarning: This process (pid=118) is multi-threaded, use of fork() may lead to deadlocks in the child.
  pid = os.fork()

[2025-09-25T19:21:15.993+0000] {standard_task_runner.py:63} INFO - Started process 120 to run task
[2025-09-25T19:21:15.997+0000] {standard_task_runner.py:90} INFO - Running: ['***', 'tasks', 'run', 'test_mariadb_dag', 'insert_rows', 'manual__2025-09-25T19:20:54.239298+00:00', '--job-id', '19', '--raw', '--subdir', 'DAGS_FOLDER/test_mariadb_dag.py', '--cfg-path', '/tmp/tmpv3t50swr']
[2025-09-25T19:21:16.003+0000] {standard_task_runner.py:91} INFO - Job 19: Subtask insert_rows
[2025-09-25T19:21:16.166+0000] {task_command.py:426} INFO - Running <TaskInstance: test_mariadb_dag.insert_rows manual__2025-09-25T19:20:54.239298+00:00 [running]> on host a7b25032b02c
[2025-09-25T19:21:16.350+0000] {taskinstance.py:2644} INFO - Exporting env vars: AIRFLOW_CTX_DAG_OWNER='***' AIRFLOW_CTX_DAG_ID='test_mariadb_dag' AIRFLOW_CTX_TASK_ID='insert_rows' AIRFLOW_CTX_EXECUTION_DATE='2025-09-25T19:20:54.239298+00:00' AIRFLOW_CTX_TRY_NUMBER='1' AIRFLOW_CTX_DAG_RUN_ID='manual__2025-09-25T19:20:54.239298+00:00'
[2025-09-25T19:21:16.355+0000] {taskinstance.py:430} INFO - ::endgroup::
[2025-09-25T19:21:16.357+0000] {sql.py:276} INFO - Executing: 
        INSERT INTO employees (name, salary)
        VALUES ('Alice', 50000), ('Bob', 60000)
        ON DUPLICATE KEY UPDATE salary = VALUES(salary);
        
[2025-09-25T19:21:16.387+0000] {taskinstance.py:441} INFO - ::group::Post task execution logs
[2025-09-25T19:21:16.415+0000] {taskinstance.py:2890} ERROR - Task failed with exception
Traceback (most recent call last):
  File "/home/airflow/.local/lib/python3.12/site-packages/airflow/models/taskinstance.py", line 465, in _execute_task
    result = _execute_callable(context=context, **execute_callable_kwargs)
             ^^^^^^^^^^^^^^^^^^^^^^^^^^^^^^^^^^^^^^^^^^^^^^^^^^^^^^^^^^^^^
  File "/home/airflow/.local/lib/python3.12/site-packages/airflow/models/taskinstance.py", line 432, in _execute_callable
    return execute_callable(context=context, **execute_callable_kwargs)
           ^^^^^^^^^^^^^^^^^^^^^^^^^^^^^^^^^^^^^^^^^^^^^^^^^^^^^^^^^^^^
  File "/home/airflow/.local/lib/python3.12/site-packages/airflow/models/baseoperator.py", line 400, in wrapper
    return func(self, *args, **kwargs)
           ^^^^^^^^^^^^^^^^^^^^^^^^^^^
  File "/home/airflow/.local/lib/python3.12/site-packages/airflow/providers/common/sql/operators/sql.py", line 277, in execute
    hook = self.get_db_hook()
           ^^^^^^^^^^^^^^^^^^
  File "/home/airflow/.local/lib/python3.12/site-packages/airflow/providers/common/sql/operators/sql.py", line 188, in get_db_hook
    return self._hook
           ^^^^^^^^^^
  File "/usr/local/lib/python3.12/functools.py", line 995, in __get__
    val = self.func(instance)
          ^^^^^^^^^^^^^^^^^^^
  File "/home/airflow/.local/lib/python3.12/site-packages/airflow/providers/common/sql/operators/sql.py", line 150, in _hook
    conn = BaseHook.get_connection(conn_id)
           ^^^^^^^^^^^^^^^^^^^^^^^^^^^^^^^^
  File "/home/airflow/.local/lib/python3.12/site-packages/airflow/hooks/base.py", line 83, in get_connection
    conn = Connection.get_connection_from_secrets(conn_id)
           ^^^^^^^^^^^^^^^^^^^^^^^^^^^^^^^^^^^^^^^^^^^^^^^
  File "/home/airflow/.local/lib/python3.12/site-packages/airflow/models/connection.py", line 519, in get_connection_from_secrets
    raise AirflowNotFoundException(f"The conn_id `{conn_id}` isn't defined")
airflow.exceptions.AirflowNotFoundException: The conn_id `my_mariadb` isn't defined
[2025-09-25T19:21:16.440+0000] {taskinstance.py:1205} INFO - Marking task as FAILED. dag_id=test_mariadb_dag, task_id=insert_rows, execution_date=20250925T192054, start_date=20250925T192115, end_date=20250925T192116
[2025-09-25T19:21:16.467+0000] {standard_task_runner.py:110} ERROR - Failed to execute job 19 for task insert_rows (The conn_id `my_mariadb` isn't defined; 120)
[2025-09-25T19:21:16.505+0000] {local_task_job_runner.py:240} INFO - Task exited with return code 1
[2025-09-25T19:21:16.531+0000] {warnings.py:110} WARNING - /home/***/.local/lib/python3.12/site-packages/***/models/baseoperator.py:1296: AirflowProviderDeprecationWarning: Call to deprecated class MySqlOperator. (Please use `***.providers.common.sql.operators.sql.SQLExecuteQueryOperator`.Also, you can provide `hook_params={'schema': <database>}`.)
  result = cls.__new__(cls)

[2025-09-25T19:21:16.562+0000] {taskinstance.py:3482} INFO - 0 downstream tasks scheduled from follow-on schedule check
[2025-09-25T19:21:16.567+0000] {local_task_job_runner.py:222} INFO - ::endgroup::
