[2025-10-12T09:22:57.823+0000] {local_task_job_runner.py:120} INFO - ::group::Pre task execution logs
[2025-10-12T09:22:57.873+0000] {taskinstance.py:2073} INFO - Dependencies all met for dep_context=non-requeueable deps ti=<TaskInstance: OpenFlightsDataIngestion_SSH.group_planes.truncate_table_planes manual__2025-10-12T09:22:49.894615+00:00 [queued]>
[2025-10-12T09:22:57.898+0000] {taskinstance.py:2073} INFO - Dependencies all met for dep_context=requeueable deps ti=<TaskInstance: OpenFlightsDataIngestion_SSH.group_planes.truncate_table_planes manual__2025-10-12T09:22:49.894615+00:00 [queued]>
[2025-10-12T09:22:57.899+0000] {taskinstance.py:2303} INFO - Starting attempt 1 of 1
[2025-10-12T09:22:57.937+0000] {taskinstance.py:2327} INFO - Executing <Task(PythonOperator): group_planes.truncate_table_planes> on 2025-10-12 09:22:49.894615+00:00
[2025-10-12T09:22:57.952+0000] {warnings.py:110} WARNING - /home/***/.local/lib/python3.12/site-packages/***/task/task_runner/standard_task_runner.py:61: DeprecationWarning: This process (pid=104) is multi-threaded, use of fork() may lead to deadlocks in the child.
  pid = os.fork()

[2025-10-12T09:22:57.956+0000] {standard_task_runner.py:63} INFO - Started process 113 to run task
[2025-10-12T09:22:57.955+0000] {standard_task_runner.py:90} INFO - Running: ['***', 'tasks', 'run', 'OpenFlightsDataIngestion_SSH', 'group_planes.truncate_table_planes', 'manual__2025-10-12T09:22:49.894615+00:00', '--job-id', '21', '--raw', '--subdir', 'DAGS_FOLDER/openflights_dag.py', '--cfg-path', '/tmp/tmptcxex306']
[2025-10-12T09:22:57.960+0000] {standard_task_runner.py:91} INFO - Job 21: Subtask group_planes.truncate_table_planes
[2025-10-12T09:22:58.060+0000] {task_command.py:426} INFO - Running <TaskInstance: OpenFlightsDataIngestion_SSH.group_planes.truncate_table_planes manual__2025-10-12T09:22:49.894615+00:00 [running]> on host 030cfa6c2cac
[2025-10-12T09:22:58.223+0000] {taskinstance.py:2644} INFO - Exporting env vars: AIRFLOW_CTX_DAG_OWNER='***' AIRFLOW_CTX_DAG_ID='OpenFlightsDataIngestion_SSH' AIRFLOW_CTX_TASK_ID='group_planes.truncate_table_planes' AIRFLOW_CTX_EXECUTION_DATE='2025-10-12T09:22:49.894615+00:00' AIRFLOW_CTX_TRY_NUMBER='1' AIRFLOW_CTX_DAG_RUN_ID='manual__2025-10-12T09:22:49.894615+00:00'
[2025-10-12T09:22:58.227+0000] {taskinstance.py:430} INFO - ::endgroup::
[2025-10-12T09:22:58.245+0000] {base.py:84} INFO - Using connection ID 'maria_db_default' for task execution.
[2025-10-12T09:22:58.247+0000] {mariadb_hook.py:37} INFO - Connecting to MariaDB database: 
[2025-10-12T09:22:58.253+0000] {taskinstance.py:441} INFO - ::group::Post task execution logs
[2025-10-12T09:22:58.254+0000] {taskinstance.py:2890} ERROR - Task failed with exception
Traceback (most recent call last):
  File "/home/airflow/.local/lib/python3.12/site-packages/airflow/models/taskinstance.py", line 465, in _execute_task
    result = _execute_callable(context=context, **execute_callable_kwargs)
             ^^^^^^^^^^^^^^^^^^^^^^^^^^^^^^^^^^^^^^^^^^^^^^^^^^^^^^^^^^^^^
  File "/home/airflow/.local/lib/python3.12/site-packages/airflow/models/taskinstance.py", line 432, in _execute_callable
    return execute_callable(context=context, **execute_callable_kwargs)
           ^^^^^^^^^^^^^^^^^^^^^^^^^^^^^^^^^^^^^^^^^^^^^^^^^^^^^^^^^^^^
  File "/home/airflow/.local/lib/python3.12/site-packages/airflow/models/baseoperator.py", line 400, in wrapper
    return func(self, *args, **kwargs)
           ^^^^^^^^^^^^^^^^^^^^^^^^^^^
  File "/home/airflow/.local/lib/python3.12/site-packages/airflow/operators/python.py", line 235, in execute
    return_value = self.execute_callable()
                   ^^^^^^^^^^^^^^^^^^^^^^^
  File "/home/airflow/.local/lib/python3.12/site-packages/airflow/operators/python.py", line 252, in execute_callable
    return self.python_callable(*self.op_args, **self.op_kwargs)
           ^^^^^^^^^^^^^^^^^^^^^^^^^^^^^^^^^^^^^^^^^^^^^^^^^^^^^
  File "/opt/airflow/dags/openflights_dag.py", line 38, in truncate_table_if_exists
    cursor.execute(f"TRUNCATE TABLE {schema}.{table};")
  File "/home/airflow/.local/lib/python3.12/site-packages/mariadb/cursors.py", line 351, in execute
    self._readresponse()
mariadb.OperationalError: DROP command denied to user 'myuser'@'172.18.0.6' for table `open_flights_data`.`planes`
[2025-10-12T09:22:58.277+0000] {taskinstance.py:1205} INFO - Marking task as FAILED. dag_id=OpenFlightsDataIngestion_SSH, task_id=group_planes.truncate_table_planes, execution_date=20251012T092249, start_date=20251012T092257, end_date=20251012T092258
[2025-10-12T09:22:58.299+0000] {standard_task_runner.py:110} ERROR - Failed to execute job 21 for task group_planes.truncate_table_planes (DROP command denied to user 'myuser'@'172.18.0.6' for table `open_flights_data`.`planes`; 113)
[2025-10-12T09:22:58.344+0000] {local_task_job_runner.py:240} INFO - Task exited with return code 1
[2025-10-12T09:22:58.400+0000] {taskinstance.py:3482} INFO - 0 downstream tasks scheduled from follow-on schedule check
[2025-10-12T09:22:58.407+0000] {local_task_job_runner.py:222} INFO - ::endgroup::
