[2025-10-16T17:27:11.255+0000] {local_task_job_runner.py:120} INFO - ::group::Pre task execution logs
[2025-10-16T17:27:11.280+0000] {taskinstance.py:2073} INFO - Dependencies all met for dep_context=non-requeueable deps ti=<TaskInstance: OpenFlightsDataIngestion.group_airlines.copy_via_ssh_airlines manual__2025-10-16T17:26:53.106871+00:00 [queued]>
[2025-10-16T17:27:11.293+0000] {taskinstance.py:2073} INFO - Dependencies all met for dep_context=requeueable deps ti=<TaskInstance: OpenFlightsDataIngestion.group_airlines.copy_via_ssh_airlines manual__2025-10-16T17:26:53.106871+00:00 [queued]>
[2025-10-16T17:27:11.294+0000] {taskinstance.py:2303} INFO - Starting attempt 1 of 1
[2025-10-16T17:27:11.311+0000] {taskinstance.py:2327} INFO - Executing <Task(SFTPOperator): group_airlines.copy_via_ssh_airlines> on 2025-10-16 17:26:53.106871+00:00
[2025-10-16T17:27:11.319+0000] {warnings.py:110} WARNING - /home/***/.local/lib/python3.12/site-packages/***/task/task_runner/standard_task_runner.py:61: DeprecationWarning: This process (pid=585) is multi-threaded, use of fork() may lead to deadlocks in the child.
  pid = os.fork()

[2025-10-16T17:27:11.322+0000] {standard_task_runner.py:63} INFO - Started process 641 to run task
[2025-10-16T17:27:11.322+0000] {standard_task_runner.py:90} INFO - Running: ['***', 'tasks', 'run', 'OpenFlightsDataIngestion', 'group_airlines.copy_via_ssh_airlines', 'manual__2025-10-16T17:26:53.106871+00:00', '--job-id', '72', '--raw', '--subdir', 'DAGS_FOLDER/openflights_dag.py', '--cfg-path', '/tmp/tmpzm0e_qx9']
[2025-10-16T17:27:11.326+0000] {standard_task_runner.py:91} INFO - Job 72: Subtask group_airlines.copy_via_ssh_airlines
[2025-10-16T17:27:11.389+0000] {task_command.py:426} INFO - Running <TaskInstance: OpenFlightsDataIngestion.group_airlines.copy_via_ssh_airlines manual__2025-10-16T17:26:53.106871+00:00 [running]> on host e6b42f39be87
[2025-10-16T17:27:11.490+0000] {taskinstance.py:2644} INFO - Exporting env vars: AIRFLOW_CTX_DAG_OWNER='***' AIRFLOW_CTX_DAG_ID='OpenFlightsDataIngestion' AIRFLOW_CTX_TASK_ID='group_airlines.copy_via_ssh_airlines' AIRFLOW_CTX_EXECUTION_DATE='2025-10-16T17:26:53.106871+00:00' AIRFLOW_CTX_TRY_NUMBER='1' AIRFLOW_CTX_DAG_RUN_ID='manual__2025-10-16T17:26:53.106871+00:00'
[2025-10-16T17:27:11.492+0000] {taskinstance.py:430} INFO - ::endgroup::
[2025-10-16T17:27:11.492+0000] {sftp.py:158} INFO - sftp_hook/ssh_hook not provided or invalid. Trying ssh_conn_id to create SFTPHook.
[2025-10-16T17:27:11.502+0000] {base.py:84} INFO - Using connection ID 'mariadb_ssh_connection' for task execution.
[2025-10-16T17:27:11.503+0000] {ssh.py:301} WARNING - No Host Key Verification. This won't protect against Man-In-The-Middle attacks
[2025-10-16T17:27:11.511+0000] {transport.py:1909} INFO - Connected (version 2.0, client OpenSSH_10.0)
[2025-10-16T17:27:11.590+0000] {transport.py:1909} INFO - Authentication (password) failed.
[2025-10-16T17:27:11.592+0000] {ssh.py:343} INFO - Failed to connect. Sleeping before retry attempt 1
[2025-10-16T17:27:15.053+0000] {transport.py:1909} INFO - Connected (version 2.0, client OpenSSH_10.0)
[2025-10-16T17:27:15.120+0000] {transport.py:1909} INFO - Authentication (password) failed.
[2025-10-16T17:27:15.121+0000] {ssh.py:343} INFO - Failed to connect. Sleeping before retry attempt 2
[2025-10-16T17:27:18.379+0000] {transport.py:1909} INFO - Connected (version 2.0, client OpenSSH_10.0)
[2025-10-16T17:27:18.445+0000] {transport.py:1909} INFO - Authentication (password) failed.
[2025-10-16T17:27:18.446+0000] {taskinstance.py:441} INFO - ::group::Post task execution logs
[2025-10-16T17:27:18.458+0000] {taskinstance.py:2890} ERROR - Task failed with exception
Traceback (most recent call last):
  File "/home/airflow/.local/lib/python3.12/site-packages/airflow/providers/sftp/operators/sftp.py", line 185, in execute
    self.sftp_hook.create_directory(remote_folder)
  File "/home/airflow/.local/lib/python3.12/site-packages/airflow/providers/sftp/hooks/sftp.py", line 211, in create_directory
    conn = self.get_conn()
           ^^^^^^^^^^^^^^^
  File "/home/airflow/.local/lib/python3.12/site-packages/airflow/providers/sftp/hooks/sftp.py", line 126, in get_conn
    self.conn = super().get_conn().open_sftp()
                ^^^^^^^^^^^^^^^^^^
  File "/home/airflow/.local/lib/python3.12/site-packages/airflow/providers/ssh/hooks/ssh.py", line 347, in get_conn
    for attempt in Retrying(
  File "/home/airflow/.local/lib/python3.12/site-packages/tenacity/__init__.py", line 347, in __iter__
    do = self.iter(retry_state=retry_state)
         ^^^^^^^^^^^^^^^^^^^^^^^^^^^^^^^^^^
  File "/home/airflow/.local/lib/python3.12/site-packages/tenacity/__init__.py", line 325, in iter
    raise retry_exc.reraise()
          ^^^^^^^^^^^^^^^^^^^
  File "/home/airflow/.local/lib/python3.12/site-packages/tenacity/__init__.py", line 158, in reraise
    raise self.last_attempt.result()
          ^^^^^^^^^^^^^^^^^^^^^^^^^^
  File "/usr/local/lib/python3.12/concurrent/futures/_base.py", line 449, in result
    return self.__get_result()
           ^^^^^^^^^^^^^^^^^^^
  File "/usr/local/lib/python3.12/concurrent/futures/_base.py", line 401, in __get_result
    raise self._exception
  File "/home/airflow/.local/lib/python3.12/site-packages/airflow/providers/ssh/hooks/ssh.py", line 354, in get_conn
    client.connect(**connect_kwargs)
  File "/home/airflow/.local/lib/python3.12/site-packages/paramiko/client.py", line 485, in connect
    self._auth(
  File "/home/airflow/.local/lib/python3.12/site-packages/paramiko/client.py", line 818, in _auth
    raise saved_exception
  File "/home/airflow/.local/lib/python3.12/site-packages/paramiko/client.py", line 805, in _auth
    self._transport.auth_password(username, password)
  File "/home/airflow/.local/lib/python3.12/site-packages/paramiko/transport.py", line 1603, in auth_password
    return self.auth_handler.wait_for_response(my_event)
           ^^^^^^^^^^^^^^^^^^^^^^^^^^^^^^^^^^^^^^^^^^^^^
  File "/home/airflow/.local/lib/python3.12/site-packages/paramiko/auth_handler.py", line 263, in wait_for_response
    raise e
paramiko.ssh_exception.AuthenticationException: Authentication failed.

During handling of the above exception, another exception occurred:

Traceback (most recent call last):
  File "/home/airflow/.local/lib/python3.12/site-packages/airflow/models/taskinstance.py", line 465, in _execute_task
    result = _execute_callable(context=context, **execute_callable_kwargs)
             ^^^^^^^^^^^^^^^^^^^^^^^^^^^^^^^^^^^^^^^^^^^^^^^^^^^^^^^^^^^^^
  File "/home/airflow/.local/lib/python3.12/site-packages/airflow/models/taskinstance.py", line 432, in _execute_callable
    return execute_callable(context=context, **execute_callable_kwargs)
           ^^^^^^^^^^^^^^^^^^^^^^^^^^^^^^^^^^^^^^^^^^^^^^^^^^^^^^^^^^^^
  File "/home/airflow/.local/lib/python3.12/site-packages/airflow/models/baseoperator.py", line 400, in wrapper
    return func(self, *args, **kwargs)
           ^^^^^^^^^^^^^^^^^^^^^^^^^^^
  File "/home/airflow/.local/lib/python3.12/site-packages/airflow/providers/sftp/operators/sftp.py", line 191, in execute
    raise AirflowException(f"Error while transferring {file_msg}, error: {e}")
airflow.exceptions.AirflowException: Error while transferring None, error: Authentication failed.
[2025-10-16T17:27:18.472+0000] {taskinstance.py:1205} INFO - Marking task as FAILED. dag_id=OpenFlightsDataIngestion, task_id=group_airlines.copy_via_ssh_airlines, execution_date=20251016T172653, start_date=20251016T172711, end_date=20251016T172718
[2025-10-16T17:27:18.490+0000] {standard_task_runner.py:110} ERROR - Failed to execute job 72 for task group_airlines.copy_via_ssh_airlines (Error while transferring None, error: Authentication failed.; 641)
[2025-10-16T17:27:18.524+0000] {local_task_job_runner.py:240} INFO - Task exited with return code 1
[2025-10-16T17:27:18.572+0000] {taskinstance.py:3482} INFO - 0 downstream tasks scheduled from follow-on schedule check
[2025-10-16T17:27:18.580+0000] {local_task_job_runner.py:222} INFO - ::endgroup::
