[2025-10-12T20:35:40.855+0000] {local_task_job_runner.py:120} INFO - ::group::Pre task execution logs
[2025-10-12T20:35:40.892+0000] {taskinstance.py:2073} INFO - Dependencies all met for dep_context=non-requeueable deps ti=<TaskInstance: OpenFlightsDataIngestion_SFTP.group_airports.create_table_airports manual__2025-10-12T20:35:30.313529+00:00 [queued]>
[2025-10-12T20:35:40.907+0000] {taskinstance.py:2073} INFO - Dependencies all met for dep_context=requeueable deps ti=<TaskInstance: OpenFlightsDataIngestion_SFTP.group_airports.create_table_airports manual__2025-10-12T20:35:30.313529+00:00 [queued]>
[2025-10-12T20:35:40.908+0000] {taskinstance.py:2303} INFO - Starting attempt 1 of 1
[2025-10-12T20:35:40.929+0000] {taskinstance.py:2327} INFO - Executing <Task(PythonOperator): group_airports.create_table_airports> on 2025-10-12 20:35:30.313529+00:00
[2025-10-12T20:35:40.941+0000] {warnings.py:110} WARNING - /home/***/.local/lib/python3.12/site-packages/***/task/task_runner/standard_task_runner.py:61: DeprecationWarning: This process (pid=113) is multi-threaded, use of fork() may lead to deadlocks in the child.
  pid = os.fork()

[2025-10-12T20:35:40.944+0000] {standard_task_runner.py:63} INFO - Started process 124 to run task
[2025-10-12T20:35:40.945+0000] {standard_task_runner.py:90} INFO - Running: ['***', 'tasks', 'run', 'OpenFlightsDataIngestion_SFTP', 'group_airports.create_table_airports', 'manual__2025-10-12T20:35:30.313529+00:00', '--job-id', '23', '--raw', '--subdir', 'DAGS_FOLDER/openflights_dag.py', '--cfg-path', '/tmp/tmph2zhkwws']
[2025-10-12T20:35:40.949+0000] {standard_task_runner.py:91} INFO - Job 23: Subtask group_airports.create_table_airports
[2025-10-12T20:35:41.023+0000] {task_command.py:426} INFO - Running <TaskInstance: OpenFlightsDataIngestion_SFTP.group_airports.create_table_airports manual__2025-10-12T20:35:30.313529+00:00 [running]> on host e507ee2c0f57
[2025-10-12T20:35:41.162+0000] {taskinstance.py:2644} INFO - Exporting env vars: AIRFLOW_CTX_DAG_OWNER='***' AIRFLOW_CTX_DAG_ID='OpenFlightsDataIngestion_SFTP' AIRFLOW_CTX_TASK_ID='group_airports.create_table_airports' AIRFLOW_CTX_EXECUTION_DATE='2025-10-12T20:35:30.313529+00:00' AIRFLOW_CTX_TRY_NUMBER='1' AIRFLOW_CTX_DAG_RUN_ID='manual__2025-10-12T20:35:30.313529+00:00'
[2025-10-12T20:35:41.167+0000] {taskinstance.py:430} INFO - ::endgroup::
[2025-10-12T20:35:41.181+0000] {base.py:84} INFO - Using connection ID 'maria_db_default' for task execution.
[2025-10-12T20:35:41.183+0000] {mariadb_hook.py:37} INFO - Connecting to MariaDB database: 
[2025-10-12T20:35:41.187+0000] {taskinstance.py:441} INFO - ::group::Post task execution logs
[2025-10-12T20:35:41.188+0000] {taskinstance.py:2890} ERROR - Task failed with exception
Traceback (most recent call last):
  File "/home/airflow/.local/lib/python3.12/site-packages/airflow/models/taskinstance.py", line 465, in _execute_task
    result = _execute_callable(context=context, **execute_callable_kwargs)
             ^^^^^^^^^^^^^^^^^^^^^^^^^^^^^^^^^^^^^^^^^^^^^^^^^^^^^^^^^^^^^
  File "/home/airflow/.local/lib/python3.12/site-packages/airflow/models/taskinstance.py", line 432, in _execute_callable
    return execute_callable(context=context, **execute_callable_kwargs)
           ^^^^^^^^^^^^^^^^^^^^^^^^^^^^^^^^^^^^^^^^^^^^^^^^^^^^^^^^^^^^
  File "/home/airflow/.local/lib/python3.12/site-packages/airflow/models/baseoperator.py", line 400, in wrapper
    return func(self, *args, **kwargs)
           ^^^^^^^^^^^^^^^^^^^^^^^^^^^
  File "/home/airflow/.local/lib/python3.12/site-packages/airflow/operators/python.py", line 235, in execute
    return_value = self.execute_callable()
                   ^^^^^^^^^^^^^^^^^^^^^^^
  File "/home/airflow/.local/lib/python3.12/site-packages/airflow/operators/python.py", line 252, in execute_callable
    return self.python_callable(*self.op_args, **self.op_kwargs)
           ^^^^^^^^^^^^^^^^^^^^^^^^^^^^^^^^^^^^^^^^^^^^^^^^^^^^^
  File "/opt/airflow/dags/openflights_dag.py", line 39, in create_table
    cursor.execute(ddl_content)
  File "/home/airflow/.local/lib/python3.12/site-packages/mariadb/cursors.py", line 351, in execute
    self._readresponse()
mariadb.OperationalError: Unknown storage engine 'ColumnStore'
[2025-10-12T20:35:41.206+0000] {taskinstance.py:1205} INFO - Marking task as FAILED. dag_id=OpenFlightsDataIngestion_SFTP, task_id=group_airports.create_table_airports, execution_date=20251012T203530, start_date=20251012T203540, end_date=20251012T203541
[2025-10-12T20:35:41.225+0000] {standard_task_runner.py:110} ERROR - Failed to execute job 23 for task group_airports.create_table_airports (Unknown storage engine 'ColumnStore'; 124)
[2025-10-12T20:35:41.251+0000] {local_task_job_runner.py:240} INFO - Task exited with return code 1
[2025-10-12T20:35:41.347+0000] {taskinstance.py:3482} INFO - 0 downstream tasks scheduled from follow-on schedule check
[2025-10-12T20:35:41.352+0000] {local_task_job_runner.py:222} INFO - ::endgroup::
