[2025-10-16T17:21:58.337+0000] {local_task_job_runner.py:120} INFO - ::group::Pre task execution logs
[2025-10-16T17:21:58.362+0000] {taskinstance.py:2073} INFO - Dependencies all met for dep_context=non-requeueable deps ti=<TaskInstance: OpenFlightsDataIngestion.group_airports.copy_via_ssh_airports manual__2025-10-16T17:21:26.859802+00:00 [queued]>
[2025-10-16T17:21:58.373+0000] {taskinstance.py:2073} INFO - Dependencies all met for dep_context=requeueable deps ti=<TaskInstance: OpenFlightsDataIngestion.group_airports.copy_via_ssh_airports manual__2025-10-16T17:21:26.859802+00:00 [queued]>
[2025-10-16T17:21:58.374+0000] {taskinstance.py:2303} INFO - Starting attempt 1 of 1
[2025-10-16T17:21:58.391+0000] {taskinstance.py:2327} INFO - Executing <Task(SFTPOperator): group_airports.copy_via_ssh_airports> on 2025-10-16 17:21:26.859802+00:00
[2025-10-16T17:21:58.398+0000] {warnings.py:110} WARNING - /home/***/.local/lib/python3.12/site-packages/***/task/task_runner/standard_task_runner.py:61: DeprecationWarning: This process (pid=312) is multi-threaded, use of fork() may lead to deadlocks in the child.
  pid = os.fork()

[2025-10-16T17:21:58.400+0000] {standard_task_runner.py:63} INFO - Started process 344 to run task
[2025-10-16T17:21:58.401+0000] {standard_task_runner.py:90} INFO - Running: ['***', 'tasks', 'run', 'OpenFlightsDataIngestion', 'group_airports.copy_via_ssh_airports', 'manual__2025-10-16T17:21:26.859802+00:00', '--job-id', '50', '--raw', '--subdir', 'DAGS_FOLDER/openflights_dag.py', '--cfg-path', '/tmp/tmpxg1ws5uf']
[2025-10-16T17:21:58.404+0000] {standard_task_runner.py:91} INFO - Job 50: Subtask group_airports.copy_via_ssh_airports
[2025-10-16T17:21:58.462+0000] {task_command.py:426} INFO - Running <TaskInstance: OpenFlightsDataIngestion.group_airports.copy_via_ssh_airports manual__2025-10-16T17:21:26.859802+00:00 [running]> on host e6b42f39be87
[2025-10-16T17:21:58.581+0000] {taskinstance.py:2644} INFO - Exporting env vars: AIRFLOW_CTX_DAG_OWNER='***' AIRFLOW_CTX_DAG_ID='OpenFlightsDataIngestion' AIRFLOW_CTX_TASK_ID='group_airports.copy_via_ssh_airports' AIRFLOW_CTX_EXECUTION_DATE='2025-10-16T17:21:26.859802+00:00' AIRFLOW_CTX_TRY_NUMBER='1' AIRFLOW_CTX_DAG_RUN_ID='manual__2025-10-16T17:21:26.859802+00:00'
[2025-10-16T17:21:58.584+0000] {taskinstance.py:430} INFO - ::endgroup::
[2025-10-16T17:21:58.585+0000] {sftp.py:158} INFO - sftp_hook/ssh_hook not provided or invalid. Trying ssh_conn_id to create SFTPHook.
[2025-10-16T17:21:58.600+0000] {base.py:84} INFO - Using connection ID 'mariadb_ssh_connection' for task execution.
[2025-10-16T17:21:58.601+0000] {ssh.py:301} WARNING - No Host Key Verification. This won't protect against Man-In-The-Middle attacks
[2025-10-16T17:21:58.603+0000] {ssh.py:343} INFO - Failed to connect. Sleeping before retry attempt 1
[2025-10-16T17:22:02.855+0000] {ssh.py:343} INFO - Failed to connect. Sleeping before retry attempt 2
[2025-10-16T17:22:07.309+0000] {taskinstance.py:441} INFO - ::group::Post task execution logs
[2025-10-16T17:22:07.323+0000] {taskinstance.py:2890} ERROR - Task failed with exception
Traceback (most recent call last):
  File "/home/airflow/.local/lib/python3.12/site-packages/airflow/providers/sftp/operators/sftp.py", line 185, in execute
    self.sftp_hook.create_directory(remote_folder)
  File "/home/airflow/.local/lib/python3.12/site-packages/airflow/providers/sftp/hooks/sftp.py", line 211, in create_directory
    conn = self.get_conn()
           ^^^^^^^^^^^^^^^
  File "/home/airflow/.local/lib/python3.12/site-packages/airflow/providers/sftp/hooks/sftp.py", line 126, in get_conn
    self.conn = super().get_conn().open_sftp()
                ^^^^^^^^^^^^^^^^^^
  File "/home/airflow/.local/lib/python3.12/site-packages/airflow/providers/ssh/hooks/ssh.py", line 347, in get_conn
    for attempt in Retrying(
  File "/home/airflow/.local/lib/python3.12/site-packages/tenacity/__init__.py", line 347, in __iter__
    do = self.iter(retry_state=retry_state)
         ^^^^^^^^^^^^^^^^^^^^^^^^^^^^^^^^^^
  File "/home/airflow/.local/lib/python3.12/site-packages/tenacity/__init__.py", line 325, in iter
    raise retry_exc.reraise()
          ^^^^^^^^^^^^^^^^^^^
  File "/home/airflow/.local/lib/python3.12/site-packages/tenacity/__init__.py", line 158, in reraise
    raise self.last_attempt.result()
          ^^^^^^^^^^^^^^^^^^^^^^^^^^
  File "/usr/local/lib/python3.12/concurrent/futures/_base.py", line 449, in result
    return self.__get_result()
           ^^^^^^^^^^^^^^^^^^^
  File "/usr/local/lib/python3.12/concurrent/futures/_base.py", line 401, in __get_result
    raise self._exception
  File "/home/airflow/.local/lib/python3.12/site-packages/airflow/providers/ssh/hooks/ssh.py", line 354, in get_conn
    client.connect(**connect_kwargs)
  File "/home/airflow/.local/lib/python3.12/site-packages/paramiko/client.py", line 409, in connect
    raise NoValidConnectionsError(errors)
paramiko.ssh_exception.NoValidConnectionsError: [Errno None] Unable to connect to port 22 on 172.18.0.2

During handling of the above exception, another exception occurred:

Traceback (most recent call last):
  File "/home/airflow/.local/lib/python3.12/site-packages/airflow/models/taskinstance.py", line 465, in _execute_task
    result = _execute_callable(context=context, **execute_callable_kwargs)
             ^^^^^^^^^^^^^^^^^^^^^^^^^^^^^^^^^^^^^^^^^^^^^^^^^^^^^^^^^^^^^
  File "/home/airflow/.local/lib/python3.12/site-packages/airflow/models/taskinstance.py", line 432, in _execute_callable
    return execute_callable(context=context, **execute_callable_kwargs)
           ^^^^^^^^^^^^^^^^^^^^^^^^^^^^^^^^^^^^^^^^^^^^^^^^^^^^^^^^^^^^
  File "/home/airflow/.local/lib/python3.12/site-packages/airflow/models/baseoperator.py", line 400, in wrapper
    return func(self, *args, **kwargs)
           ^^^^^^^^^^^^^^^^^^^^^^^^^^^
  File "/home/airflow/.local/lib/python3.12/site-packages/airflow/providers/sftp/operators/sftp.py", line 191, in execute
    raise AirflowException(f"Error while transferring {file_msg}, error: {e}")
airflow.exceptions.AirflowException: Error while transferring None, error: [Errno None] Unable to connect to port 22 on 172.18.0.2
[2025-10-16T17:22:07.334+0000] {taskinstance.py:1205} INFO - Marking task as FAILED. dag_id=OpenFlightsDataIngestion, task_id=group_airports.copy_via_ssh_airports, execution_date=20251016T172126, start_date=20251016T172158, end_date=20251016T172207
[2025-10-16T17:22:07.357+0000] {standard_task_runner.py:110} ERROR - Failed to execute job 50 for task group_airports.copy_via_ssh_airports (Error while transferring None, error: [Errno None] Unable to connect to port 22 on 172.18.0.2; 344)
[2025-10-16T17:22:07.405+0000] {local_task_job_runner.py:240} INFO - Task exited with return code 1
[2025-10-16T17:22:07.439+0000] {taskinstance.py:3482} INFO - 0 downstream tasks scheduled from follow-on schedule check
[2025-10-16T17:22:07.445+0000] {local_task_job_runner.py:222} INFO - ::endgroup::
