[2025-10-13T11:44:23.227+0000] {local_task_job_runner.py:120} INFO - ::group::Pre task execution logs
[2025-10-13T11:44:23.264+0000] {taskinstance.py:2073} INFO - Dependencies all met for dep_context=non-requeueable deps ti=<TaskInstance: OpenFlightsDataIngestion_SFTP.group_airports.create_table_airports manual__2025-10-13T11:44:01.548927+00:00 [queued]>
[2025-10-13T11:44:23.280+0000] {taskinstance.py:2073} INFO - Dependencies all met for dep_context=requeueable deps ti=<TaskInstance: OpenFlightsDataIngestion_SFTP.group_airports.create_table_airports manual__2025-10-13T11:44:01.548927+00:00 [queued]>
[2025-10-13T11:44:23.281+0000] {taskinstance.py:2303} INFO - Starting attempt 1 of 1
[2025-10-13T11:44:23.299+0000] {taskinstance.py:2327} INFO - Executing <Task(PythonOperator): group_airports.create_table_airports> on 2025-10-13 11:44:01.548927+00:00
[2025-10-13T11:44:23.312+0000] {warnings.py:110} WARNING - /home/***/.local/lib/python3.12/site-packages/***/task/task_runner/standard_task_runner.py:61: DeprecationWarning: This process (pid=98) is multi-threaded, use of fork() may lead to deadlocks in the child.
  pid = os.fork()

[2025-10-13T11:44:23.314+0000] {standard_task_runner.py:63} INFO - Started process 101 to run task
[2025-10-13T11:44:23.315+0000] {standard_task_runner.py:90} INFO - Running: ['***', 'tasks', 'run', 'OpenFlightsDataIngestion_SFTP', 'group_airports.create_table_airports', 'manual__2025-10-13T11:44:01.548927+00:00', '--job-id', '16', '--raw', '--subdir', 'DAGS_FOLDER/openflights_dag.py', '--cfg-path', '/tmp/tmpjwoj_gdt']
[2025-10-13T11:44:23.318+0000] {standard_task_runner.py:91} INFO - Job 16: Subtask group_airports.create_table_airports
[2025-10-13T11:44:23.381+0000] {task_command.py:426} INFO - Running <TaskInstance: OpenFlightsDataIngestion_SFTP.group_airports.create_table_airports manual__2025-10-13T11:44:01.548927+00:00 [running]> on host 165b2a8d6d15
[2025-10-13T11:44:23.495+0000] {taskinstance.py:2644} INFO - Exporting env vars: AIRFLOW_CTX_DAG_OWNER='***' AIRFLOW_CTX_DAG_ID='OpenFlightsDataIngestion_SFTP' AIRFLOW_CTX_TASK_ID='group_airports.create_table_airports' AIRFLOW_CTX_EXECUTION_DATE='2025-10-13T11:44:01.548927+00:00' AIRFLOW_CTX_TRY_NUMBER='1' AIRFLOW_CTX_DAG_RUN_ID='manual__2025-10-13T11:44:01.548927+00:00'
[2025-10-13T11:44:23.498+0000] {taskinstance.py:430} INFO - ::endgroup::
[2025-10-13T11:44:23.510+0000] {base.py:84} INFO - Using connection ID 'maria_db_default' for task execution.
[2025-10-13T11:44:23.511+0000] {mariadb_hook.py:37} INFO - Connecting to MariaDB database: 
[2025-10-13T11:44:23.518+0000] {taskinstance.py:441} INFO - ::group::Post task execution logs
[2025-10-13T11:44:23.518+0000] {taskinstance.py:2890} ERROR - Task failed with exception
Traceback (most recent call last):
  File "/home/airflow/.local/lib/python3.12/site-packages/airflow/models/taskinstance.py", line 465, in _execute_task
    result = _execute_callable(context=context, **execute_callable_kwargs)
             ^^^^^^^^^^^^^^^^^^^^^^^^^^^^^^^^^^^^^^^^^^^^^^^^^^^^^^^^^^^^^
  File "/home/airflow/.local/lib/python3.12/site-packages/airflow/models/taskinstance.py", line 432, in _execute_callable
    return execute_callable(context=context, **execute_callable_kwargs)
           ^^^^^^^^^^^^^^^^^^^^^^^^^^^^^^^^^^^^^^^^^^^^^^^^^^^^^^^^^^^^
  File "/home/airflow/.local/lib/python3.12/site-packages/airflow/models/baseoperator.py", line 400, in wrapper
    return func(self, *args, **kwargs)
           ^^^^^^^^^^^^^^^^^^^^^^^^^^^
  File "/home/airflow/.local/lib/python3.12/site-packages/airflow/operators/python.py", line 235, in execute
    return_value = self.execute_callable()
                   ^^^^^^^^^^^^^^^^^^^^^^^
  File "/home/airflow/.local/lib/python3.12/site-packages/airflow/operators/python.py", line 252, in execute_callable
    return self.python_callable(*self.op_args, **self.op_kwargs)
           ^^^^^^^^^^^^^^^^^^^^^^^^^^^^^^^^^^^^^^^^^^^^^^^^^^^^^
  File "/opt/airflow/dags/openflights_dag.py", line 39, in create_table
    cursor.execute(ddl_content)
  File "/home/airflow/.local/lib/python3.12/site-packages/mariadb/cursors.py", line 351, in execute
    self._readresponse()
mariadb.ProgrammingError: Unknown database 'open_flights_data'
[2025-10-13T11:44:23.534+0000] {taskinstance.py:1205} INFO - Marking task as FAILED. dag_id=OpenFlightsDataIngestion_SFTP, task_id=group_airports.create_table_airports, execution_date=20251013T114401, start_date=20251013T114423, end_date=20251013T114423
[2025-10-13T11:44:23.550+0000] {standard_task_runner.py:110} ERROR - Failed to execute job 16 for task group_airports.create_table_airports (Unknown database 'open_flights_data'; 101)
[2025-10-13T11:44:23.578+0000] {local_task_job_runner.py:240} INFO - Task exited with return code 1
[2025-10-13T11:44:23.612+0000] {taskinstance.py:3482} INFO - 0 downstream tasks scheduled from follow-on schedule check
[2025-10-13T11:44:23.617+0000] {local_task_job_runner.py:222} INFO - ::endgroup::
