[2025-10-16T18:38:15.425+0000] {local_task_job_runner.py:120} INFO - ::group::Pre task execution logs
[2025-10-16T18:38:15.450+0000] {taskinstance.py:2073} INFO - Dependencies all met for dep_context=non-requeueable deps ti=<TaskInstance: OpenFlightsDataIngestion.group_routes.copy_via_ssh_routes manual__2025-10-16T18:37:45.932349+00:00 [queued]>
[2025-10-16T18:38:15.462+0000] {taskinstance.py:2073} INFO - Dependencies all met for dep_context=requeueable deps ti=<TaskInstance: OpenFlightsDataIngestion.group_routes.copy_via_ssh_routes manual__2025-10-16T18:37:45.932349+00:00 [queued]>
[2025-10-16T18:38:15.463+0000] {taskinstance.py:2303} INFO - Starting attempt 1 of 1
[2025-10-16T18:38:15.481+0000] {taskinstance.py:2327} INFO - Executing <Task(SFTPOperator): group_routes.copy_via_ssh_routes> on 2025-10-16 18:37:45.932349+00:00
[2025-10-16T18:38:15.489+0000] {warnings.py:110} WARNING - /home/***/.local/lib/python3.12/site-packages/***/task/task_runner/standard_task_runner.py:61: DeprecationWarning: This process (pid=302) is multi-threaded, use of fork() may lead to deadlocks in the child.
  pid = os.fork()

[2025-10-16T18:38:15.492+0000] {standard_task_runner.py:63} INFO - Started process 349 to run task
[2025-10-16T18:38:15.492+0000] {standard_task_runner.py:90} INFO - Running: ['***', 'tasks', 'run', 'OpenFlightsDataIngestion', 'group_routes.copy_via_ssh_routes', 'manual__2025-10-16T18:37:45.932349+00:00', '--job-id', '179', '--raw', '--subdir', 'DAGS_FOLDER/openflights_dag.py', '--cfg-path', '/tmp/tmp2zwx3qr2']
[2025-10-16T18:38:15.496+0000] {standard_task_runner.py:91} INFO - Job 179: Subtask group_routes.copy_via_ssh_routes
[2025-10-16T18:38:15.561+0000] {task_command.py:426} INFO - Running <TaskInstance: OpenFlightsDataIngestion.group_routes.copy_via_ssh_routes manual__2025-10-16T18:37:45.932349+00:00 [running]> on host e6b42f39be87
[2025-10-16T18:38:15.671+0000] {taskinstance.py:2644} INFO - Exporting env vars: AIRFLOW_CTX_DAG_OWNER='***' AIRFLOW_CTX_DAG_ID='OpenFlightsDataIngestion' AIRFLOW_CTX_TASK_ID='group_routes.copy_via_ssh_routes' AIRFLOW_CTX_EXECUTION_DATE='2025-10-16T18:37:45.932349+00:00' AIRFLOW_CTX_TRY_NUMBER='1' AIRFLOW_CTX_DAG_RUN_ID='manual__2025-10-16T18:37:45.932349+00:00'
[2025-10-16T18:38:15.675+0000] {taskinstance.py:430} INFO - ::endgroup::
[2025-10-16T18:38:15.676+0000] {sftp.py:158} INFO - sftp_hook/ssh_hook not provided or invalid. Trying ssh_conn_id to create SFTPHook.
[2025-10-16T18:38:15.692+0000] {base.py:84} INFO - Using connection ID 'mariadb_ssh_connection' for task execution.
[2025-10-16T18:38:16.008+0000] {ssh.py:301} WARNING - No Host Key Verification. This won't protect against Man-In-The-Middle attacks
[2025-10-16T18:38:16.015+0000] {transport.py:1909} INFO - Connected (version 2.0, client OpenSSH_10.0)
[2025-10-16T18:38:16.085+0000] {transport.py:1909} INFO - Authentication (publickey) failed.
[2025-10-16T18:38:16.097+0000] {transport.py:1909} INFO - Authentication (password) failed.
[2025-10-16T18:38:16.098+0000] {ssh.py:343} INFO - Failed to connect. Sleeping before retry attempt 1
[2025-10-16T18:38:19.360+0000] {transport.py:1909} INFO - Connected (version 2.0, client OpenSSH_10.0)
[2025-10-16T18:38:19.434+0000] {transport.py:1909} INFO - Authentication (publickey) failed.
[2025-10-16T18:38:19.446+0000] {transport.py:1909} INFO - Authentication (password) failed.
[2025-10-16T18:38:19.447+0000] {ssh.py:343} INFO - Failed to connect. Sleeping before retry attempt 2
[2025-10-16T18:38:22.706+0000] {transport.py:1909} INFO - Connected (version 2.0, client OpenSSH_10.0)
[2025-10-16T18:38:22.777+0000] {transport.py:1909} INFO - Authentication (publickey) failed.
[2025-10-16T18:38:22.789+0000] {transport.py:1909} INFO - Authentication (password) failed.
[2025-10-16T18:38:22.790+0000] {taskinstance.py:441} INFO - ::group::Post task execution logs
[2025-10-16T18:38:22.803+0000] {taskinstance.py:2890} ERROR - Task failed with exception
Traceback (most recent call last):
  File "/home/airflow/.local/lib/python3.12/site-packages/airflow/providers/sftp/operators/sftp.py", line 185, in execute
    self.sftp_hook.create_directory(remote_folder)
  File "/home/airflow/.local/lib/python3.12/site-packages/airflow/providers/sftp/hooks/sftp.py", line 211, in create_directory
    conn = self.get_conn()
           ^^^^^^^^^^^^^^^
  File "/home/airflow/.local/lib/python3.12/site-packages/airflow/providers/sftp/hooks/sftp.py", line 126, in get_conn
    self.conn = super().get_conn().open_sftp()
                ^^^^^^^^^^^^^^^^^^
  File "/home/airflow/.local/lib/python3.12/site-packages/airflow/providers/ssh/hooks/ssh.py", line 347, in get_conn
    for attempt in Retrying(
  File "/home/airflow/.local/lib/python3.12/site-packages/tenacity/__init__.py", line 347, in __iter__
    do = self.iter(retry_state=retry_state)
         ^^^^^^^^^^^^^^^^^^^^^^^^^^^^^^^^^^
  File "/home/airflow/.local/lib/python3.12/site-packages/tenacity/__init__.py", line 325, in iter
    raise retry_exc.reraise()
          ^^^^^^^^^^^^^^^^^^^
  File "/home/airflow/.local/lib/python3.12/site-packages/tenacity/__init__.py", line 158, in reraise
    raise self.last_attempt.result()
          ^^^^^^^^^^^^^^^^^^^^^^^^^^
  File "/usr/local/lib/python3.12/concurrent/futures/_base.py", line 449, in result
    return self.__get_result()
           ^^^^^^^^^^^^^^^^^^^
  File "/usr/local/lib/python3.12/concurrent/futures/_base.py", line 401, in __get_result
    raise self._exception
  File "/home/airflow/.local/lib/python3.12/site-packages/airflow/providers/ssh/hooks/ssh.py", line 354, in get_conn
    client.connect(**connect_kwargs)
  File "/home/airflow/.local/lib/python3.12/site-packages/paramiko/client.py", line 485, in connect
    self._auth(
  File "/home/airflow/.local/lib/python3.12/site-packages/paramiko/client.py", line 818, in _auth
    raise saved_exception
  File "/home/airflow/.local/lib/python3.12/site-packages/paramiko/client.py", line 805, in _auth
    self._transport.auth_password(username, password)
  File "/home/airflow/.local/lib/python3.12/site-packages/paramiko/transport.py", line 1603, in auth_password
    return self.auth_handler.wait_for_response(my_event)
           ^^^^^^^^^^^^^^^^^^^^^^^^^^^^^^^^^^^^^^^^^^^^^
  File "/home/airflow/.local/lib/python3.12/site-packages/paramiko/auth_handler.py", line 263, in wait_for_response
    raise e
paramiko.ssh_exception.AuthenticationException: Authentication failed.

During handling of the above exception, another exception occurred:

Traceback (most recent call last):
  File "/home/airflow/.local/lib/python3.12/site-packages/airflow/models/taskinstance.py", line 465, in _execute_task
    result = _execute_callable(context=context, **execute_callable_kwargs)
             ^^^^^^^^^^^^^^^^^^^^^^^^^^^^^^^^^^^^^^^^^^^^^^^^^^^^^^^^^^^^^
  File "/home/airflow/.local/lib/python3.12/site-packages/airflow/models/taskinstance.py", line 432, in _execute_callable
    return execute_callable(context=context, **execute_callable_kwargs)
           ^^^^^^^^^^^^^^^^^^^^^^^^^^^^^^^^^^^^^^^^^^^^^^^^^^^^^^^^^^^^
  File "/home/airflow/.local/lib/python3.12/site-packages/airflow/models/baseoperator.py", line 400, in wrapper
    return func(self, *args, **kwargs)
           ^^^^^^^^^^^^^^^^^^^^^^^^^^^
  File "/home/airflow/.local/lib/python3.12/site-packages/airflow/providers/sftp/operators/sftp.py", line 191, in execute
    raise AirflowException(f"Error while transferring {file_msg}, error: {e}")
airflow.exceptions.AirflowException: Error while transferring None, error: Authentication failed.
[2025-10-16T18:38:22.819+0000] {taskinstance.py:1205} INFO - Marking task as FAILED. dag_id=OpenFlightsDataIngestion, task_id=group_routes.copy_via_ssh_routes, execution_date=20251016T183745, start_date=20251016T183815, end_date=20251016T183822
[2025-10-16T18:38:22.842+0000] {standard_task_runner.py:110} ERROR - Failed to execute job 179 for task group_routes.copy_via_ssh_routes (Error while transferring None, error: Authentication failed.; 349)
[2025-10-16T18:38:22.896+0000] {local_task_job_runner.py:240} INFO - Task exited with return code 1
[2025-10-16T18:38:22.975+0000] {taskinstance.py:3482} INFO - 0 downstream tasks scheduled from follow-on schedule check
[2025-10-16T18:38:22.981+0000] {local_task_job_runner.py:222} INFO - ::endgroup::
