[2025-10-16T17:29:45.079+0000] {local_task_job_runner.py:120} INFO - ::group::Pre task execution logs
[2025-10-16T17:29:45.106+0000] {taskinstance.py:2073} INFO - Dependencies all met for dep_context=non-requeueable deps ti=<TaskInstance: OpenFlightsDataIngestion.group_airports.copy_via_ssh_airports manual__2025-10-16T17:29:27.088107+00:00 [queued]>
[2025-10-16T17:29:45.119+0000] {taskinstance.py:2073} INFO - Dependencies all met for dep_context=requeueable deps ti=<TaskInstance: OpenFlightsDataIngestion.group_airports.copy_via_ssh_airports manual__2025-10-16T17:29:27.088107+00:00 [queued]>
[2025-10-16T17:29:45.120+0000] {taskinstance.py:2303} INFO - Starting attempt 1 of 1
[2025-10-16T17:29:45.138+0000] {taskinstance.py:2327} INFO - Executing <Task(SFTPOperator): group_airports.copy_via_ssh_airports> on 2025-10-16 17:29:27.088107+00:00
[2025-10-16T17:29:45.147+0000] {warnings.py:110} WARNING - /home/***/.local/lib/python3.12/site-packages/***/task/task_runner/standard_task_runner.py:61: DeprecationWarning: This process (pid=903) is multi-threaded, use of fork() may lead to deadlocks in the child.
  pid = os.fork()

[2025-10-16T17:29:45.150+0000] {standard_task_runner.py:63} INFO - Started process 956 to run task
[2025-10-16T17:29:45.150+0000] {standard_task_runner.py:90} INFO - Running: ['***', 'tasks', 'run', 'OpenFlightsDataIngestion', 'group_airports.copy_via_ssh_airports', 'manual__2025-10-16T17:29:27.088107+00:00', '--job-id', '90', '--raw', '--subdir', 'DAGS_FOLDER/openflights_dag.py', '--cfg-path', '/tmp/tmp7nvnh7xl']
[2025-10-16T17:29:45.153+0000] {standard_task_runner.py:91} INFO - Job 90: Subtask group_airports.copy_via_ssh_airports
[2025-10-16T17:29:45.222+0000] {task_command.py:426} INFO - Running <TaskInstance: OpenFlightsDataIngestion.group_airports.copy_via_ssh_airports manual__2025-10-16T17:29:27.088107+00:00 [running]> on host e6b42f39be87
[2025-10-16T17:29:45.346+0000] {taskinstance.py:2644} INFO - Exporting env vars: AIRFLOW_CTX_DAG_OWNER='***' AIRFLOW_CTX_DAG_ID='OpenFlightsDataIngestion' AIRFLOW_CTX_TASK_ID='group_airports.copy_via_ssh_airports' AIRFLOW_CTX_EXECUTION_DATE='2025-10-16T17:29:27.088107+00:00' AIRFLOW_CTX_TRY_NUMBER='1' AIRFLOW_CTX_DAG_RUN_ID='manual__2025-10-16T17:29:27.088107+00:00'
[2025-10-16T17:29:45.349+0000] {taskinstance.py:430} INFO - ::endgroup::
[2025-10-16T17:29:45.350+0000] {sftp.py:158} INFO - sftp_hook/ssh_hook not provided or invalid. Trying ssh_conn_id to create SFTPHook.
[2025-10-16T17:29:45.362+0000] {base.py:84} INFO - Using connection ID 'mariadb_ssh_connection' for task execution.
[2025-10-16T17:29:45.363+0000] {ssh.py:301} WARNING - No Host Key Verification. This won't protect against Man-In-The-Middle attacks
[2025-10-16T17:29:45.372+0000] {transport.py:1909} INFO - Connected (version 2.0, client OpenSSH_10.0)
[2025-10-16T17:29:45.440+0000] {transport.py:1909} INFO - Authentication (password) failed.
[2025-10-16T17:29:45.441+0000] {ssh.py:343} INFO - Failed to connect. Sleeping before retry attempt 1
[2025-10-16T17:29:49.339+0000] {transport.py:1909} INFO - Connected (version 2.0, client OpenSSH_10.0)
[2025-10-16T17:29:49.405+0000] {transport.py:1909} INFO - Authentication (password) failed.
[2025-10-16T17:29:49.406+0000] {ssh.py:343} INFO - Failed to connect. Sleeping before retry attempt 2
[2025-10-16T17:29:53.913+0000] {transport.py:1909} ERROR - Exception (client): Error reading SSH protocol banner
[2025-10-16T17:29:53.917+0000] {transport.py:1907} ERROR - Traceback (most recent call last):
[2025-10-16T17:29:53.917+0000] {transport.py:1907} ERROR -   File "/home/***/.local/lib/python3.12/site-packages/paramiko/transport.py", line 2327, in _check_banner
[2025-10-16T17:29:53.918+0000] {transport.py:1907} ERROR -     buf = self.packetizer.readline(timeout)
[2025-10-16T17:29:53.918+0000] {transport.py:1907} ERROR -           ^^^^^^^^^^^^^^^^^^^^^^^^^^^^^^^^^
[2025-10-16T17:29:53.919+0000] {transport.py:1907} ERROR -   File "/home/***/.local/lib/python3.12/site-packages/paramiko/packet.py", line 381, in readline
[2025-10-16T17:29:53.919+0000] {transport.py:1907} ERROR -     buf += self._read_timeout(timeout)
[2025-10-16T17:29:53.920+0000] {transport.py:1907} ERROR -            ^^^^^^^^^^^^^^^^^^^^^^^^^^^
[2025-10-16T17:29:53.920+0000] {transport.py:1907} ERROR -   File "/home/***/.local/lib/python3.12/site-packages/paramiko/packet.py", line 618, in _read_timeout
[2025-10-16T17:29:53.921+0000] {transport.py:1907} ERROR -     raise EOFError()
[2025-10-16T17:29:53.921+0000] {transport.py:1907} ERROR - EOFError
[2025-10-16T17:29:53.922+0000] {transport.py:1907} ERROR - 
[2025-10-16T17:29:53.922+0000] {transport.py:1907} ERROR - During handling of the above exception, another exception occurred:
[2025-10-16T17:29:53.923+0000] {transport.py:1907} ERROR - 
[2025-10-16T17:29:53.923+0000] {transport.py:1907} ERROR - Traceback (most recent call last):
[2025-10-16T17:29:53.924+0000] {transport.py:1907} ERROR -   File "/home/***/.local/lib/python3.12/site-packages/paramiko/transport.py", line 2143, in run
[2025-10-16T17:29:53.925+0000] {transport.py:1907} ERROR -     self._check_banner()
[2025-10-16T17:29:53.925+0000] {transport.py:1907} ERROR -   File "/home/***/.local/lib/python3.12/site-packages/paramiko/transport.py", line 2331, in _check_banner
[2025-10-16T17:29:53.925+0000] {transport.py:1907} ERROR -     raise SSHException(
[2025-10-16T17:29:53.926+0000] {transport.py:1907} ERROR - paramiko.ssh_exception.SSHException: Error reading SSH protocol banner
[2025-10-16T17:29:53.926+0000] {transport.py:1907} ERROR - 
[2025-10-16T17:29:53.927+0000] {taskinstance.py:441} INFO - ::group::Post task execution logs
[2025-10-16T17:29:53.938+0000] {taskinstance.py:2890} ERROR - Task failed with exception
Traceback (most recent call last):
  File "/home/airflow/.local/lib/python3.12/site-packages/paramiko/transport.py", line 2327, in _check_banner
    buf = self.packetizer.readline(timeout)
          ^^^^^^^^^^^^^^^^^^^^^^^^^^^^^^^^^
  File "/home/airflow/.local/lib/python3.12/site-packages/paramiko/packet.py", line 381, in readline
    buf += self._read_timeout(timeout)
           ^^^^^^^^^^^^^^^^^^^^^^^^^^^
  File "/home/airflow/.local/lib/python3.12/site-packages/paramiko/packet.py", line 618, in _read_timeout
    raise EOFError()
EOFError

During handling of the above exception, another exception occurred:

Traceback (most recent call last):
  File "/home/airflow/.local/lib/python3.12/site-packages/airflow/providers/sftp/operators/sftp.py", line 185, in execute
    self.sftp_hook.create_directory(remote_folder)
  File "/home/airflow/.local/lib/python3.12/site-packages/airflow/providers/sftp/hooks/sftp.py", line 211, in create_directory
    conn = self.get_conn()
           ^^^^^^^^^^^^^^^
  File "/home/airflow/.local/lib/python3.12/site-packages/airflow/providers/sftp/hooks/sftp.py", line 126, in get_conn
    self.conn = super().get_conn().open_sftp()
                ^^^^^^^^^^^^^^^^^^
  File "/home/airflow/.local/lib/python3.12/site-packages/airflow/providers/ssh/hooks/ssh.py", line 347, in get_conn
    for attempt in Retrying(
  File "/home/airflow/.local/lib/python3.12/site-packages/tenacity/__init__.py", line 347, in __iter__
    do = self.iter(retry_state=retry_state)
         ^^^^^^^^^^^^^^^^^^^^^^^^^^^^^^^^^^
  File "/home/airflow/.local/lib/python3.12/site-packages/tenacity/__init__.py", line 325, in iter
    raise retry_exc.reraise()
          ^^^^^^^^^^^^^^^^^^^
  File "/home/airflow/.local/lib/python3.12/site-packages/tenacity/__init__.py", line 158, in reraise
    raise self.last_attempt.result()
          ^^^^^^^^^^^^^^^^^^^^^^^^^^
  File "/usr/local/lib/python3.12/concurrent/futures/_base.py", line 449, in result
    return self.__get_result()
           ^^^^^^^^^^^^^^^^^^^
  File "/usr/local/lib/python3.12/concurrent/futures/_base.py", line 401, in __get_result
    raise self._exception
  File "/home/airflow/.local/lib/python3.12/site-packages/airflow/providers/ssh/hooks/ssh.py", line 354, in get_conn
    client.connect(**connect_kwargs)
  File "/home/airflow/.local/lib/python3.12/site-packages/paramiko/client.py", line 451, in connect
    t.start_client(timeout=timeout)
  File "/home/airflow/.local/lib/python3.12/site-packages/paramiko/transport.py", line 738, in start_client
    raise e
  File "/home/airflow/.local/lib/python3.12/site-packages/paramiko/transport.py", line 2143, in run
    self._check_banner()
  File "/home/airflow/.local/lib/python3.12/site-packages/paramiko/transport.py", line 2331, in _check_banner
    raise SSHException(
paramiko.ssh_exception.SSHException: Error reading SSH protocol banner

During handling of the above exception, another exception occurred:

Traceback (most recent call last):
  File "/home/airflow/.local/lib/python3.12/site-packages/airflow/models/taskinstance.py", line 465, in _execute_task
    result = _execute_callable(context=context, **execute_callable_kwargs)
             ^^^^^^^^^^^^^^^^^^^^^^^^^^^^^^^^^^^^^^^^^^^^^^^^^^^^^^^^^^^^^
  File "/home/airflow/.local/lib/python3.12/site-packages/airflow/models/taskinstance.py", line 432, in _execute_callable
    return execute_callable(context=context, **execute_callable_kwargs)
           ^^^^^^^^^^^^^^^^^^^^^^^^^^^^^^^^^^^^^^^^^^^^^^^^^^^^^^^^^^^^
  File "/home/airflow/.local/lib/python3.12/site-packages/airflow/models/baseoperator.py", line 400, in wrapper
    return func(self, *args, **kwargs)
           ^^^^^^^^^^^^^^^^^^^^^^^^^^^
  File "/home/airflow/.local/lib/python3.12/site-packages/airflow/providers/sftp/operators/sftp.py", line 191, in execute
    raise AirflowException(f"Error while transferring {file_msg}, error: {e}")
airflow.exceptions.AirflowException: Error while transferring None, error: Error reading SSH protocol banner
[2025-10-16T17:29:53.946+0000] {taskinstance.py:1205} INFO - Marking task as FAILED. dag_id=OpenFlightsDataIngestion, task_id=group_airports.copy_via_ssh_airports, execution_date=20251016T172927, start_date=20251016T172945, end_date=20251016T172953
[2025-10-16T17:29:53.963+0000] {standard_task_runner.py:110} ERROR - Failed to execute job 90 for task group_airports.copy_via_ssh_airports (Error while transferring None, error: Error reading SSH protocol banner; 956)
[2025-10-16T17:29:53.995+0000] {local_task_job_runner.py:240} INFO - Task exited with return code 1
[2025-10-16T17:29:54.028+0000] {taskinstance.py:3482} INFO - 0 downstream tasks scheduled from follow-on schedule check
[2025-10-16T17:29:54.032+0000] {local_task_job_runner.py:222} INFO - ::endgroup::
